<?xml version="1.0"?>
<robot xmlns:xacro = "http://www.ros.org/wiki/xacro" name="robot">

    <material name="white">
        <color rgba="1.0 1.0 1.0 1.0"/>    
    </material>

    <material name="orange">
        <color rgba="1.0 0.3 0.1 1.0"/>    
    </material>
    
    <material name="blue">
        <color rgba="0.2 0.2 1.0 1.0"/>    
    </material>

    <material name="black">
        <color rgba="0 0 0 1.0"/>    
    </material>

    <material name="silver">
        <color rgba="0.75 0.75 0.75 1.0"/>
    </material>

    <material name="grey">
        <color rgba="0.5 0.5 0.5 1.0"/>
    </material>

    <!-- BASE LINK -->

    <link name="base_link">
        <origin xyz="0.0 0.0 0.0"/>
    </link>

    <!-- CHASSIS -->

    <joint name="base_to_chassis1" type="fixed">
        <parent link="base_link"/>
        <child link="chassis_1"/>
        <origin xyz="0 0 0.075"/>
    </joint>

    <link name="chassis_1">
        <visual>
            <origin xyz="0 0 0.0"/>
            <geometry>
                <box size="0.45 0.32 0.05"/>
            </geometry>
            <material name="silver"/>
        </visual>
        <collision>
            <origin xyz="0 0 0.0"/>
            <geometry>
                <box size="0.45 0.32 0.05"/>
            </geometry>
        </collision>
        <inertial>
            <mass value="7.49"/>
            <origin xyz="0 0 0"/>
            <inertia ixx="0.0649" ixy="0" ixz="0" iyy="0.1433" iyz="0" izz="0.1926"/>
        </inertial>
    </link>

    <joint name="chassis1_to_chassis2" type="fixed">
        <parent link="chassis_1"/>
        <child link="chassis_2"/>
        <origin xyz="0 0 0.035"/>
    </joint>

    <link name="chassis_2">
        <visual>
            <origin xyz="0 0 0.0"/>
            <geometry>
                <box size="0.43 0.32 0.02"/>
            </geometry>
            <material name="white"/>
        </visual>
        <collision>
            <origin xyz="0 0 0.0"/>
            <geometry>
                <box size="0.43 0.32 0.02"/>
            </geometry>
        </collision>
        <inertial>
            <mass value="2.86"/>
            <origin xyz="0 0 0"/>
            <inertia ixx="0.0244" ixy="0" ixz="0" iyy="0.0441" iyz="0" izz="0.0686"/>
        </inertial>
    </link>

    <joint name="chassis2_to_chassis3" type="fixed">
        <parent link="chassis_2"/>
        <child link="chassis_3"/>
        <origin xyz="0 0 0.03"/>
    </joint>

    <link name="chassis_3">
        <visual>
            <origin xyz="0 0 0.0"/>
            <geometry>
                <box size="0.45 0.32 0.04"/>
            </geometry>
            <material name="silver"/>
        </visual>
        <collision>
            <origin xyz="0 0 0.0"/>
            <geometry>
                <box size="0.45 0.32 0.04"/>
            </geometry>
        </collision>
        <inertial>
            <mass value="5.99"/>
            <origin xyz="0 0 0"/>
            <inertia ixx="0.0517" ixy="0" ixz="0" iyy="0.1017" iyz="0" izz="0.1515"/>
        </inertial>
    </link>

    <!-- DRIVE WHEELS -->

    <!-- LEFT WHEEL LINK -->

    <joint name="left_wheel_joint" type="continuous">
        <parent link="base_link"/>
        <child link="left_wheel"/>
        <origin xyz="0.0 0.18 0.075" rpy="-${pi/2} 0.0 0.0"/>
        <axis xyz="0.0 0.0 1.0"/>
    </joint>

    <link name="left_wheel">
        <visual>
            <origin xyz="0.0 0.0 0.0"/>
            <geometry>
                <cylinder radius="0.075" length="0.04"/>
            </geometry>
            <material name="black"/>
        </visual>
        <collision>
            <origin xyz="0.0 0.0 0.0"/>
            <geometry>
                <cylinder radius="0.075" length="0.04"/>
            </geometry>
        </collision>
        <inertial>
            <mass value="1.06"/>
            <origin xyz="0 0 0"/>
            <inertia ixx="0.0026" ixy="0" ixz="0" iyy="0.0026" iyz="0" izz="0.00297"/>
        </inertial>
    </link>
    
    <!-- RIGHT WHEEL LINK -->

    <joint name="right_wheel_joint" type="continuous">
        <parent link="base_link"/>
        <child link="right_wheel"/>
        <origin xyz="0.0 -0.18 0.075" rpy="${pi/2} 0.0 0.0"/>
        <axis xyz="0.0 0.0 -1.0"/>
    </joint>

    <link name="right_wheel">
        <visual>
            <origin xyz="0.0 0.0 0.0"/>
            <geometry>
                <cylinder radius="0.075" length="0.04"/>
            </geometry>
            <material name="black"/>
        </visual>
        <collision>
            <origin xyz="0.0 0.0 0.0"/>
            <geometry>
                <cylinder radius="0.075" length="0.04"/>
            </geometry>
        </collision>
        <inertial>
            <mass value="1.06"/>
            <origin xyz="0 0 0"/>
            <inertia ixx="0.0026" ixy="0" ixz="0" iyy="0.0026" iyz="0" izz="0.00297"/>
        </inertial>
    </link>

    <!-- CASTER WHEEL LINK -->

    <joint name="caster_wheel_joint1" type="fixed">
        <parent link="chassis_1"/>
        <child link="front_caster_wheel"/>
        <origin xyz="0.145 0.0 -0.0375"/>
        <axis xyz="0.0 0.0 0.0"/>
    </joint>

    <link name="front_caster_wheel">
        <visual>
            <origin xyz="0.0 0.0 0.0"/>
            <geometry>
                <sphere radius="0.0375"/>
            </geometry>
            <material name="grey"/>
        </visual>
        <collision>
            <origin xyz="0.0 0.0 0.0"/>
            <geometry>
                <sphere radius="0.0375"/>
            </geometry>
            <material name="grey"/>
        </collision>
        <inertial>
            <mass value="0.33"/>
            <origin xyz="0 0 0"/>
            <inertia ixx="0.00037" ixy="0" ixz="0" iyy="0.00037" iyz="0" izz="0.00037"/>
        </inertial>
    </link>

    <joint name="caster_wheel_joint2" type="fixed">
        <parent link="chassis_1"/>
        <child link="back_caster_wheel"/>
        <origin xyz="-0.145 0.0 -0.0375"/>
        <axis xyz="0.0 0.0 0.0"/>
    </joint>

    <link name="back_caster_wheel">
        <visual>
            <origin xyz="0.0 0.0 0.0"/>
            <geometry>
                <sphere radius="0.0375"/>
            </geometry>
            <material name="grey"/>
        </visual>
        <collision>
            <origin xyz="0.0 0.0 0.0"/>
            <geometry>
                <sphere radius="0.0375"/>
            </geometry>
        </collision>
        <inertial>
            <mass value="0.33"/>
            <origin xyz="0 0 0"/>
            <inertia ixx="0.00037" ixy="0" ixz="0" iyy="0.00037" iyz="0" izz="0.00037"/>
        </inertial>
    </link>

</robot>